<?xml version="1.0" encoding="UTF-8"?>
<testng-results ignored="6" total="9" passed="2" failed="1" skipped="0">
  <reporter-output>
    <line>
      <![CDATA[--> Reporter log in passed test <--]]>
    </line>
    <line>
      <![CDATA[ --> Reporter logs of failed test <---]]>
    </line>
    <line>
      <![CDATA[One assertion has just passed]]>
    </line>
  </reporter-output>
  <suite started-at="2021-03-28T20:31:57Z" name="TestAll" finished-at="2021-03-28T20:31:57Z" duration-ms="221">
    <groups>
    </groups>
    <test started-at="2021-03-28T20:31:57Z" name="Add" finished-at="2021-03-28T20:31:57Z" duration-ms="166">
      <class name="com.kaz.jenkins.CalculatorTest">
        <test-method signature="addTest()[pri:0, instance:com.kaz.jenkins.CalculatorTest@706eab5d]" started-at="2021-03-28T20:31:57Z" name="addTest" description="Add test for Calculator" finished-at="2021-03-28T20:31:57Z" duration-ms="49" status="PASS">
          <reporter-output>
            <line>
              <![CDATA[--> Reporter log in passed test <--]]>
            </line>
          </reporter-output>
        </test-method> <!-- addTest -->
      </class> <!-- com.kaz.jenkins.CalculatorTest -->
    </test> <!-- Add -->
    <test started-at="2021-03-28T20:31:57Z" name="Divide" finished-at="2021-03-28T20:31:57Z" duration-ms="10">
      <class name="com.kaz.jenkins.CalculatorTest">
        <test-method signature="divideTest()[pri:0, instance:com.kaz.jenkins.CalculatorTest@46a953cf]" started-at="2021-03-28T20:31:57Z" name="divideTest" description="Divide test for Calculator" finished-at="2021-03-28T20:31:57Z" duration-ms="2" status="PASS">
          <reporter-output>
          </reporter-output>
        </test-method> <!-- divideTest -->
      </class> <!-- com.kaz.jenkins.CalculatorTest -->
    </test> <!-- Divide -->
    <test started-at="2021-03-28T20:31:57Z" name="Fail" finished-at="2021-03-28T20:31:57Z" duration-ms="16">
      <class name="com.kaz.jenkins.CalculatorTest">
        <test-method signature="failedTest()[pri:0, instance:com.kaz.jenkins.CalculatorTest@56f521c6]" started-at="2021-03-28T20:31:57Z" name="failedTest" description="Failed test for Calculator" finished-at="2021-03-28T20:31:57Z" duration-ms="2" status="FAIL">
          <exception class="java.lang.AssertionError">
            <message>
              <![CDATA[This should be [FALSE] but was [TRUE] ==== expected:<false> but was:<true>]]>
            </message>
            <full-stacktrace>
              <![CDATA[java.lang.AssertionError: This should be [FALSE] but was [TRUE] ==== expected:<false> but was:<true>
at org.junit.Assert.fail(Assert.java:88)
at org.junit.Assert.failNotEquals(Assert.java:834)
at org.junit.Assert.assertEquals(Assert.java:118)
at com.kaz.jenkins.CalculatorTest.failedTest(CalculatorTest.java:61)
at java.base/jdk.internal.reflect.NativeMethodAccessorImpl.invoke0(Native Method)
at java.base/jdk.internal.reflect.NativeMethodAccessorImpl.invoke(NativeMethodAccessorImpl.java:62)
at java.base/jdk.internal.reflect.DelegatingMethodAccessorImpl.invoke(DelegatingMethodAccessorImpl.java:43)
at java.base/java.lang.reflect.Method.invoke(Method.java:564)
at org.testng.internal.MethodInvocationHelper.invokeMethod(MethodInvocationHelper.java:124)
at org.testng.internal.Invoker.invokeMethod(Invoker.java:583)
at org.testng.internal.Invoker.invokeTestMethod(Invoker.java:719)
at org.testng.internal.Invoker.invokeTestMethods(Invoker.java:989)
at org.testng.internal.TestMethodWorker.invokeTestMethods(TestMethodWorker.java:125)
at org.testng.internal.TestMethodWorker.run(TestMethodWorker.java:109)
at org.testng.TestRunner.privateRun(TestRunner.java:648)
at org.testng.TestRunner.run(TestRunner.java:505)
at org.testng.SuiteRunner.runTest(SuiteRunner.java:455)
at org.testng.SuiteRunner.runSequentially(SuiteRunner.java:450)
at org.testng.SuiteRunner.privateRun(SuiteRunner.java:415)
at org.testng.SuiteRunner.run(SuiteRunner.java:364)
at org.testng.SuiteRunnerWorker.runSuite(SuiteRunnerWorker.java:52)
at org.testng.SuiteRunnerWorker.run(SuiteRunnerWorker.java:84)
at org.testng.TestNG.runSuitesSequentially(TestNG.java:1208)
at org.testng.TestNG.runSuitesLocally(TestNG.java:1137)
at org.testng.TestNG.runSuites(TestNG.java:1049)
at org.testng.TestNG.run(TestNG.java:1017)
at org.apache.maven.surefire.testng.TestNGExecutor.run(TestNGExecutor.java:283)
at org.apache.maven.surefire.testng.TestNGXmlTestSuite.execute(TestNGXmlTestSuite.java:75)
at org.apache.maven.surefire.testng.TestNGProvider.invoke(TestNGProvider.java:120)
at org.apache.maven.surefire.booter.ForkedBooter.invokeProviderInSameClassLoader(ForkedBooter.java:386)
at org.apache.maven.surefire.booter.ForkedBooter.runSuitesInProcess(ForkedBooter.java:323)
at org.apache.maven.surefire.booter.ForkedBooter.main(ForkedBooter.java:143)
]]>
            </full-stacktrace>
          </exception> <!-- java.lang.AssertionError -->
          <reporter-output>
            <line>
              <![CDATA[ --> Reporter logs of failed test <---]]>
            </line>
            <line>
              <![CDATA[One assertion has just passed]]>
            </line>
          </reporter-output>
        </test-method> <!-- failedTest -->
      </class> <!-- com.kaz.jenkins.CalculatorTest -->
    </test> <!-- Fail -->
  </suite> <!-- TestAll -->
</testng-results>
