<?xml version="1.0" encoding="UTF-8"?>
<!-- Generated by org.testng.reporters.JUnitReportReporter -->
<testsuite hostname="Julias-MacBook-Pro.local" failures="1" tests="3" name="com.kaz.jenkins.CalculatorTest" time="5.095" errors="0" timestamp="28 Mar 2021 21:01:16 GMT" skipped="0">
  <testcase classname="com.kaz.jenkins.CalculatorTest" name="failedTest" time="0.002">
    <failure message="This should be [FALSE] but was [TRUE] ==== expected:&lt;false&gt; but was:&lt;true&gt;" type="java.lang.AssertionError">
      <![CDATA[java.lang.AssertionError: This should be [FALSE] but was [TRUE] ==== expected:<false> but was:<true>
at org.junit.Assert.fail(Assert.java:88)
at org.junit.Assert.failNotEquals(Assert.java:834)
at org.junit.Assert.assertEquals(Assert.java:118)
at com.kaz.jenkins.CalculatorTest.failedTest(CalculatorTest.java:47)
at java.base/jdk.internal.reflect.NativeMethodAccessorImpl.invoke0(Native Method)
at java.base/jdk.internal.reflect.NativeMethodAccessorImpl.invoke(NativeMethodAccessorImpl.java:62)
at java.base/jdk.internal.reflect.DelegatingMethodAccessorImpl.invoke(DelegatingMethodAccessorImpl.java:43)
at java.base/java.lang.reflect.Method.invoke(Method.java:564)
at org.testng.internal.MethodInvocationHelper.invokeMethod(MethodInvocationHelper.java:124)
at org.testng.internal.Invoker.invokeMethod(Invoker.java:583)
at org.testng.internal.Invoker.invokeTestMethod(Invoker.java:719)
at org.testng.internal.Invoker.invokeTestMethods(Invoker.java:989)
at org.testng.internal.TestMethodWorker.invokeTestMethods(TestMethodWorker.java:125)
at org.testng.internal.TestMethodWorker.run(TestMethodWorker.java:109)
at org.testng.TestRunner.privateRun(TestRunner.java:648)
at org.testng.TestRunner.run(TestRunner.java:505)
at org.testng.SuiteRunner.runTest(SuiteRunner.java:455)
at org.testng.SuiteRunner.runSequentially(SuiteRunner.java:450)
at org.testng.SuiteRunner.privateRun(SuiteRunner.java:415)
at org.testng.SuiteRunner.run(SuiteRunner.java:364)
at org.testng.SuiteRunnerWorker.runSuite(SuiteRunnerWorker.java:52)
at org.testng.SuiteRunnerWorker.run(SuiteRunnerWorker.java:84)
at org.testng.TestNG.runSuitesSequentially(TestNG.java:1208)
at org.testng.TestNG.runSuitesLocally(TestNG.java:1137)
at org.testng.TestNG.runSuites(TestNG.java:1049)
at org.testng.TestNG.run(TestNG.java:1017)
at org.apache.maven.surefire.testng.TestNGExecutor.run(TestNGExecutor.java:283)
at org.apache.maven.surefire.testng.TestNGXmlTestSuite.execute(TestNGXmlTestSuite.java:75)
at org.apache.maven.surefire.testng.TestNGProvider.invoke(TestNGProvider.java:120)
at org.apache.maven.surefire.booter.ForkedBooter.invokeProviderInSameClassLoader(ForkedBooter.java:386)
at org.apache.maven.surefire.booter.ForkedBooter.runSuitesInProcess(ForkedBooter.java:323)
at org.apache.maven.surefire.booter.ForkedBooter.main(ForkedBooter.java:143)
]]>
    </failure>
  </testcase> <!-- failedTest -->
  <testcase classname="com.kaz.jenkins.CalculatorTest" name="addTest" time="5.091"/>
  <testcase classname="com.kaz.jenkins.CalculatorTest" name="divideTest" time="0.002"/>
</testsuite> <!-- com.kaz.jenkins.CalculatorTest -->
